Traceback (most recent call last):
  File "/app/.heroku/python/lib/python3.6/site-packages/django/db/backends/utils.py", line 84, in _execute
    return self.cursor.execute(sql, params)
psycopg2.errors.UniqueViolation: duplicate key value violates unique constraint "django_content_type_app_label_model_76bd3d3b_uniq"
DETAIL:  Key (app_label, model)=(contact, usermessages) already exists.


The above exception was the direct cause of the following exception:

Traceback (most recent call last):
  File "manage.py", line 22, in <module>
    main()
  File "manage.py", line 18, in main
    execute_from_command_line(sys.argv)
  File "/app/.heroku/python/lib/python3.6/site-packages/django/core/management/__init__.py", line 419, in execute_from_command_line
    utility.execute()
  File "/app/.heroku/python/lib/python3.6/site-packages/django/core/management/__init__.py", line 413, in execute
    self.fetch_command(subcommand).run_from_argv(self.argv)
  File "/app/.heroku/python/lib/python3.6/site-packages/django/core/management/base.py", line 354, in run_from_argv
    self.execute(*args, **cmd_options)
  File "/app/.heroku/python/lib/python3.6/site-packages/django/core/management/base.py", line 398, in execute
    output = self.handle(*args, **options)
  File "/app/.heroku/python/lib/python3.6/site-packages/django/core/management/commands/loaddata.py", line 78, in handle
    self.loaddata(fixture_labels)
  File "/app/.heroku/python/lib/python3.6/site-packages/django/core/management/commands/loaddata.py", line 123, in loaddata
    self.load_label(fixture_label)
  File "/app/.heroku/python/lib/python3.6/site-packages/django/core/management/commands/loaddata.py", line 190, in load_label
    obj.save(using=self.using)
  File "/app/.heroku/python/lib/python3.6/site-packages/django/core/serializers/base.py", line 223, in save
    models.Model.save_base(self.object, using=using, raw=True, **kwargs)
  File "/app/.heroku/python/lib/python3.6/site-packages/django/db/models/base.py", line 765, in save_base
    force_update, using, update_fields,
  File "/app/.heroku/python/lib/python3.6/site-packages/django/db/models/base.py", line 846, in _save_table
    forced_update)
  File "/app/.heroku/python/lib/python3.6/site-packages/django/db/models/base.py", line 899, in _do_update
    return filtered._update(values) > 0
  File "/app/.heroku/python/lib/python3.6/site-packages/django/db/models/query.py", line 802, in _update
    return query.get_compiler(self.db).execute_sql(CURSOR)
  File "/app/.heroku/python/lib/python3.6/site-packages/django/db/models/sql/compiler.py", line 1535, in execute_sql
    cursor = super().execute_sql(result_type)
  File "/app/.heroku/python/lib/python3.6/site-packages/django/db/models/sql/compiler.py", line 1169, in execute_sql
    cursor.execute(sql, params)
  File "/app/.heroku/python/lib/python3.6/site-packages/django/db/backends/utils.py", line 98, in execute
    return super().execute(sql, params)
  File "/app/.heroku/python/lib/python3.6/site-packages/django/db/backends/utils.py", line 66, in execute
    return self._execute_with_wrappers(sql, params, many=False, executor=self._execute)
  File "/app/.heroku/python/lib/python3.6/site-packages/django/db/backends/utils.py", line 75, in _execute_with_wrappers
    return executor(sql, params, many, context)
  File "/app/.heroku/python/lib/python3.6/site-packages/django/db/backends/utils.py", line 84, in _execute
    return self.cursor.execute(sql, params)
  File "/app/.heroku/python/lib/python3.6/site-packages/django/db/utils.py", line 90, in __exit__
    raise dj_exc_value.with_traceback(traceback) from exc_value
  File "/app/.heroku/python/lib/python3.6/site-packages/django/db/backends/utils.py", line 84, in _execute
    return self.cursor.execute(sql, params)
django.db.utils.IntegrityError: Problem installing fixture '/app/mydata.json': Could not load contenttypes.ContentType(pk=7): duplicate key value violates unique constraint "django_content_type_app_label_model_76bd3d3b_uniq"
DETAIL:  Key (app_label, model)=(contact, usermessages) already exists.

